[2019-09-18 16:33:38,103][Thread-4:6536][task_id:django.request][exception.py:118][ERROR][Internal Server Error: /blog/up_down/]
Traceback (most recent call last):
  File "E:\python3.6\lib\site-packages\django\core\handlers\exception.py", line 35, in inner
    response = get_response(request)
  File "E:\python3.6\lib\site-packages\django\core\handlers\base.py", line 139, in _get_response
    "returned None instead." % (callback.__module__, view_name)
ValueError: The view myapp.views.blog.up_down didn't return an HttpResponse object. It returned None instead.
[2019-09-18 16:33:39,253][Thread-5:20688][task_id:django.request][exception.py:118][ERROR][Internal Server Error: /blog/up_down/]
Traceback (most recent call last):
  File "E:\python3.6\lib\site-packages\django\core\handlers\exception.py", line 35, in inner
    response = get_response(request)
  File "E:\python3.6\lib\site-packages\django\core\handlers\base.py", line 139, in _get_response
    "returned None instead." % (callback.__module__, view_name)
ValueError: The view myapp.views.blog.up_down didn't return an HttpResponse object. It returned None instead.
[2019-09-18 16:33:39,783][Thread-6:5656][task_id:django.request][exception.py:118][ERROR][Internal Server Error: /blog/up_down/]
Traceback (most recent call last):
  File "E:\python3.6\lib\site-packages\django\core\handlers\exception.py", line 35, in inner
    response = get_response(request)
  File "E:\python3.6\lib\site-packages\django\core\handlers\base.py", line 139, in _get_response
    "returned None instead." % (callback.__module__, view_name)
ValueError: The view myapp.views.blog.up_down didn't return an HttpResponse object. It returned None instead.
[2019-09-18 16:33:45,284][Thread-8:19804][task_id:django.request][exception.py:118][ERROR][Internal Server Error: /blog/up_down/]
Traceback (most recent call last):
  File "E:\python3.6\lib\site-packages\django\core\handlers\exception.py", line 35, in inner
    response = get_response(request)
  File "E:\python3.6\lib\site-packages\django\core\handlers\base.py", line 139, in _get_response
    "returned None instead." % (callback.__module__, view_name)
ValueError: The view myapp.views.blog.up_down didn't return an HttpResponse object. It returned None instead.
[2019-09-18 16:33:45,983][Thread-9:20032][task_id:django.request][exception.py:118][ERROR][Internal Server Error: /blog/up_down/]
Traceback (most recent call last):
  File "E:\python3.6\lib\site-packages\django\core\handlers\exception.py", line 35, in inner
    response = get_response(request)
  File "E:\python3.6\lib\site-packages\django\core\handlers\base.py", line 139, in _get_response
    "returned None instead." % (callback.__module__, view_name)
ValueError: The view myapp.views.blog.up_down didn't return an HttpResponse object. It returned None instead.
[2019-09-18 16:33:56,646][Thread-10:18192][task_id:django.request][exception.py:118][ERROR][Internal Server Error: /blog/up_down/]
Traceback (most recent call last):
  File "E:\python3.6\lib\site-packages\django\core\handlers\exception.py", line 35, in inner
    response = get_response(request)
  File "E:\python3.6\lib\site-packages\django\core\handlers\base.py", line 139, in _get_response
    "returned None instead." % (callback.__module__, view_name)
ValueError: The view myapp.views.blog.up_down didn't return an HttpResponse object. It returned None instead.
[2019-09-18 16:33:56,839][Thread-11:2020][task_id:django.request][exception.py:118][ERROR][Internal Server Error: /blog/up_down/]
Traceback (most recent call last):
  File "E:\python3.6\lib\site-packages\django\core\handlers\exception.py", line 35, in inner
    response = get_response(request)
  File "E:\python3.6\lib\site-packages\django\core\handlers\base.py", line 139, in _get_response
    "returned None instead." % (callback.__module__, view_name)
ValueError: The view myapp.views.blog.up_down didn't return an HttpResponse object. It returned None instead.
[2019-09-18 16:33:58,617][Thread-12:21296][task_id:django.request][exception.py:118][ERROR][Internal Server Error: /blog/up_down/]
Traceback (most recent call last):
  File "E:\python3.6\lib\site-packages\django\core\handlers\exception.py", line 35, in inner
    response = get_response(request)
  File "E:\python3.6\lib\site-packages\django\core\handlers\base.py", line 139, in _get_response
    "returned None instead." % (callback.__module__, view_name)
ValueError: The view myapp.views.blog.up_down didn't return an HttpResponse object. It returned None instead.
[2019-09-18 16:33:58,807][Thread-13:17860][task_id:django.request][exception.py:118][ERROR][Internal Server Error: /blog/up_down/]
Traceback (most recent call last):
  File "E:\python3.6\lib\site-packages\django\core\handlers\exception.py", line 35, in inner
    response = get_response(request)
  File "E:\python3.6\lib\site-packages\django\core\handlers\base.py", line 139, in _get_response
    "returned None instead." % (callback.__module__, view_name)
ValueError: The view myapp.views.blog.up_down didn't return an HttpResponse object. It returned None instead.
[2019-09-18 16:37:52,915][Thread-7:11520][task_id:django.request][exception.py:118][ERROR][Internal Server Error: /blog/up_down/]
Traceback (most recent call last):
  File "E:\python3.6\lib\site-packages\django\core\handlers\exception.py", line 35, in inner
    response = get_response(request)
  File "E:\python3.6\lib\site-packages\django\core\handlers\base.py", line 128, in _get_response
    response = self.process_exception_by_middleware(e, request)
  File "E:\python3.6\lib\site-packages\django\core\handlers\base.py", line 126, in _get_response
    response = wrapped_callback(request, *callback_args, **callback_kwargs)
  File "J:\django_bbs\webbs\myapp\views\blog.py", line 107, in up_down
    user=request.username
AttributeError: 'WSGIRequest' object has no attribute 'username'
[2019-09-18 16:37:53,098][Thread-8:16932][task_id:django.request][exception.py:118][ERROR][Internal Server Error: /blog/up_down/]
Traceback (most recent call last):
  File "E:\python3.6\lib\site-packages\django\core\handlers\exception.py", line 35, in inner
    response = get_response(request)
  File "E:\python3.6\lib\site-packages\django\core\handlers\base.py", line 128, in _get_response
    response = self.process_exception_by_middleware(e, request)
  File "E:\python3.6\lib\site-packages\django\core\handlers\base.py", line 126, in _get_response
    response = wrapped_callback(request, *callback_args, **callback_kwargs)
  File "J:\django_bbs\webbs\myapp\views\blog.py", line 107, in up_down
    user=request.username
AttributeError: 'WSGIRequest' object has no attribute 'username'
[2019-09-18 16:37:55,275][Thread-9:18644][task_id:django.request][exception.py:118][ERROR][Internal Server Error: /blog/up_down/]
Traceback (most recent call last):
  File "E:\python3.6\lib\site-packages\django\core\handlers\exception.py", line 35, in inner
    response = get_response(request)
  File "E:\python3.6\lib\site-packages\django\core\handlers\base.py", line 128, in _get_response
    response = self.process_exception_by_middleware(e, request)
  File "E:\python3.6\lib\site-packages\django\core\handlers\base.py", line 126, in _get_response
    response = wrapped_callback(request, *callback_args, **callback_kwargs)
  File "J:\django_bbs\webbs\myapp\views\blog.py", line 107, in up_down
    user=request.username
AttributeError: 'WSGIRequest' object has no attribute 'username'
[2019-09-18 16:37:55,457][Thread-10:19132][task_id:django.request][exception.py:118][ERROR][Internal Server Error: /blog/up_down/]
Traceback (most recent call last):
  File "E:\python3.6\lib\site-packages\django\core\handlers\exception.py", line 35, in inner
    response = get_response(request)
  File "E:\python3.6\lib\site-packages\django\core\handlers\base.py", line 128, in _get_response
    response = self.process_exception_by_middleware(e, request)
  File "E:\python3.6\lib\site-packages\django\core\handlers\base.py", line 126, in _get_response
    response = wrapped_callback(request, *callback_args, **callback_kwargs)
  File "J:\django_bbs\webbs\myapp\views\blog.py", line 107, in up_down
    user=request.username
AttributeError: 'WSGIRequest' object has no attribute 'username'
[2019-09-19 09:55:22,219][Thread-43:13192][task_id:django.request][exception.py:118][ERROR][Internal Server Error: /blog/up_down/]
Traceback (most recent call last):
  File "J:\django_bbs\webbs\myapp\views\blog.py", line 114, in up_down
    models.ArticleUpDown.objects.create(user=user, article_id=article_id, is_up=is_up)
  File "E:\python3.6\lib\site-packages\django\db\models\manager.py", line 82, in manager_method
    return getattr(self.get_queryset(), name)(*args, **kwargs)
  File "E:\python3.6\lib\site-packages\django\db\models\query.py", line 415, in create
    obj = self.model(**kwargs)
  File "E:\python3.6\lib\site-packages\django\db\models\base.py", line 477, in __init__
    _setattr(self, field.name, rel_obj)
  File "E:\python3.6\lib\site-packages\django\db\models\fields\related_descriptors.py", line 197, in __set__
    self.field.remote_field.model._meta.object_name,
ValueError: Cannot assign "<SimpleLazyObject: <django.contrib.auth.models.AnonymousUser object at 0x048F1D90>>": "ArticleUpDown.user" must be a "UserInfo" instance.

During handling of the above exception, another exception occurred:

Traceback (most recent call last):
  File "E:\python3.6\lib\site-packages\django\core\handlers\exception.py", line 35, in inner
    response = get_response(request)
  File "E:\python3.6\lib\site-packages\django\core\handlers\base.py", line 128, in _get_response
    response = self.process_exception_by_middleware(e, request)
  File "E:\python3.6\lib\site-packages\django\core\handlers\base.py", line 126, in _get_response
    response = wrapped_callback(request, *callback_args, **callback_kwargs)
  File "J:\django_bbs\webbs\myapp\views\blog.py", line 118, in up_down
    aa=models.ArticleUpDown.objects.filter(user=user, article_id=article_id).first().is_up
  File "E:\python3.6\lib\site-packages\django\db\models\manager.py", line 82, in manager_method
    return getattr(self.get_queryset(), name)(*args, **kwargs)
  File "E:\python3.6\lib\site-packages\django\db\models\query.py", line 836, in filter
    return self._filter_or_exclude(False, *args, **kwargs)
  File "E:\python3.6\lib\site-packages\django\db\models\query.py", line 854, in _filter_or_exclude
    clone.query.add_q(Q(*args, **kwargs))
  File "E:\python3.6\lib\site-packages\django\db\models\sql\query.py", line 1252, in add_q
    clause, _ = self._add_q(q_object, self.used_aliases)
  File "E:\python3.6\lib\site-packages\django\db\models\sql\query.py", line 1276, in _add_q
    split_subq=split_subq,
  File "E:\python3.6\lib\site-packages\django\db\models\sql\query.py", line 1186, in build_filter
    self.check_related_objects(join_info.final_field, value, join_info.opts)
  File "E:\python3.6\lib\site-packages\django\db\models\sql\query.py", line 1052, in check_related_objects
    for v in value:
  File "E:\python3.6\lib\site-packages\django\utils\functional.py", line 216, in inner
    return func(self._wrapped, *args)
TypeError: 'AnonymousUser' object is not iterable
[2019-09-19 09:55:23,886][Thread-44:1524][task_id:django.request][exception.py:118][ERROR][Internal Server Error: /blog/up_down/]
Traceback (most recent call last):
  File "J:\django_bbs\webbs\myapp\views\blog.py", line 114, in up_down
    models.ArticleUpDown.objects.create(user=user, article_id=article_id, is_up=is_up)
  File "E:\python3.6\lib\site-packages\django\db\models\manager.py", line 82, in manager_method
    return getattr(self.get_queryset(), name)(*args, **kwargs)
  File "E:\python3.6\lib\site-packages\django\db\models\query.py", line 415, in create
    obj = self.model(**kwargs)
  File "E:\python3.6\lib\site-packages\django\db\models\base.py", line 477, in __init__
    _setattr(self, field.name, rel_obj)
  File "E:\python3.6\lib\site-packages\django\db\models\fields\related_descriptors.py", line 197, in __set__
    self.field.remote_field.model._meta.object_name,
ValueError: Cannot assign "<SimpleLazyObject: <django.contrib.auth.models.AnonymousUser object at 0x04791D10>>": "ArticleUpDown.user" must be a "UserInfo" instance.

During handling of the above exception, another exception occurred:

Traceback (most recent call last):
  File "E:\python3.6\lib\site-packages\django\core\handlers\exception.py", line 35, in inner
    response = get_response(request)
  File "E:\python3.6\lib\site-packages\django\core\handlers\base.py", line 128, in _get_response
    response = self.process_exception_by_middleware(e, request)
  File "E:\python3.6\lib\site-packages\django\core\handlers\base.py", line 126, in _get_response
    response = wrapped_callback(request, *callback_args, **callback_kwargs)
  File "J:\django_bbs\webbs\myapp\views\blog.py", line 118, in up_down
    aa=models.ArticleUpDown.objects.filter(user=user, article_id=article_id).first().is_up
  File "E:\python3.6\lib\site-packages\django\db\models\manager.py", line 82, in manager_method
    return getattr(self.get_queryset(), name)(*args, **kwargs)
  File "E:\python3.6\lib\site-packages\django\db\models\query.py", line 836, in filter
    return self._filter_or_exclude(False, *args, **kwargs)
  File "E:\python3.6\lib\site-packages\django\db\models\query.py", line 854, in _filter_or_exclude
    clone.query.add_q(Q(*args, **kwargs))
  File "E:\python3.6\lib\site-packages\django\db\models\sql\query.py", line 1252, in add_q
    clause, _ = self._add_q(q_object, self.used_aliases)
  File "E:\python3.6\lib\site-packages\django\db\models\sql\query.py", line 1276, in _add_q
    split_subq=split_subq,
  File "E:\python3.6\lib\site-packages\django\db\models\sql\query.py", line 1186, in build_filter
    self.check_related_objects(join_info.final_field, value, join_info.opts)
  File "E:\python3.6\lib\site-packages\django\db\models\sql\query.py", line 1052, in check_related_objects
    for v in value:
  File "E:\python3.6\lib\site-packages\django\utils\functional.py", line 216, in inner
    return func(self._wrapped, *args)
TypeError: 'AnonymousUser' object is not iterable
[2019-09-19 09:55:24,086][Thread-45:1596][task_id:django.request][exception.py:118][ERROR][Internal Server Error: /blog/up_down/]
Traceback (most recent call last):
  File "J:\django_bbs\webbs\myapp\views\blog.py", line 114, in up_down
    models.ArticleUpDown.objects.create(user=user, article_id=article_id, is_up=is_up)
  File "E:\python3.6\lib\site-packages\django\db\models\manager.py", line 82, in manager_method
    return getattr(self.get_queryset(), name)(*args, **kwargs)
  File "E:\python3.6\lib\site-packages\django\db\models\query.py", line 415, in create
    obj = self.model(**kwargs)
  File "E:\python3.6\lib\site-packages\django\db\models\base.py", line 477, in __init__
    _setattr(self, field.name, rel_obj)
  File "E:\python3.6\lib\site-packages\django\db\models\fields\related_descriptors.py", line 197, in __set__
    self.field.remote_field.model._meta.object_name,
ValueError: Cannot assign "<SimpleLazyObject: <django.contrib.auth.models.AnonymousUser object at 0x046B67F0>>": "ArticleUpDown.user" must be a "UserInfo" instance.

During handling of the above exception, another exception occurred:

Traceback (most recent call last):
  File "E:\python3.6\lib\site-packages\django\core\handlers\exception.py", line 35, in inner
    response = get_response(request)
  File "E:\python3.6\lib\site-packages\django\core\handlers\base.py", line 128, in _get_response
    response = self.process_exception_by_middleware(e, request)
  File "E:\python3.6\lib\site-packages\django\core\handlers\base.py", line 126, in _get_response
    response = wrapped_callback(request, *callback_args, **callback_kwargs)
  File "J:\django_bbs\webbs\myapp\views\blog.py", line 118, in up_down
    aa=models.ArticleUpDown.objects.filter(user=user, article_id=article_id).first().is_up
  File "E:\python3.6\lib\site-packages\django\db\models\manager.py", line 82, in manager_method
    return getattr(self.get_queryset(), name)(*args, **kwargs)
  File "E:\python3.6\lib\site-packages\django\db\models\query.py", line 836, in filter
    return self._filter_or_exclude(False, *args, **kwargs)
  File "E:\python3.6\lib\site-packages\django\db\models\query.py", line 854, in _filter_or_exclude
    clone.query.add_q(Q(*args, **kwargs))
  File "E:\python3.6\lib\site-packages\django\db\models\sql\query.py", line 1252, in add_q
    clause, _ = self._add_q(q_object, self.used_aliases)
  File "E:\python3.6\lib\site-packages\django\db\models\sql\query.py", line 1276, in _add_q
    split_subq=split_subq,
  File "E:\python3.6\lib\site-packages\django\db\models\sql\query.py", line 1186, in build_filter
    self.check_related_objects(join_info.final_field, value, join_info.opts)
  File "E:\python3.6\lib\site-packages\django\db\models\sql\query.py", line 1052, in check_related_objects
    for v in value:
  File "E:\python3.6\lib\site-packages\django\utils\functional.py", line 216, in inner
    return func(self._wrapped, *args)
TypeError: 'AnonymousUser' object is not iterable
[2019-09-19 09:55:24,810][Thread-46:13092][task_id:django.request][exception.py:118][ERROR][Internal Server Error: /blog/up_down/]
Traceback (most recent call last):
  File "J:\django_bbs\webbs\myapp\views\blog.py", line 114, in up_down
    models.ArticleUpDown.objects.create(user=user, article_id=article_id, is_up=is_up)
  File "E:\python3.6\lib\site-packages\django\db\models\manager.py", line 82, in manager_method
    return getattr(self.get_queryset(), name)(*args, **kwargs)
  File "E:\python3.6\lib\site-packages\django\db\models\query.py", line 415, in create
    obj = self.model(**kwargs)
  File "E:\python3.6\lib\site-packages\django\db\models\base.py", line 477, in __init__
    _setattr(self, field.name, rel_obj)
  File "E:\python3.6\lib\site-packages\django\db\models\fields\related_descriptors.py", line 197, in __set__
    self.field.remote_field.model._meta.object_name,
ValueError: Cannot assign "<SimpleLazyObject: <django.contrib.auth.models.AnonymousUser object at 0x0491F990>>": "ArticleUpDown.user" must be a "UserInfo" instance.

During handling of the above exception, another exception occurred:

Traceback (most recent call last):
  File "E:\python3.6\lib\site-packages\django\core\handlers\exception.py", line 35, in inner
    response = get_response(request)
  File "E:\python3.6\lib\site-packages\django\core\handlers\base.py", line 128, in _get_response
    response = self.process_exception_by_middleware(e, request)
  File "E:\python3.6\lib\site-packages\django\core\handlers\base.py", line 126, in _get_response
    response = wrapped_callback(request, *callback_args, **callback_kwargs)
  File "J:\django_bbs\webbs\myapp\views\blog.py", line 118, in up_down
    aa=models.ArticleUpDown.objects.filter(user=user, article_id=article_id).first().is_up
  File "E:\python3.6\lib\site-packages\django\db\models\manager.py", line 82, in manager_method
    return getattr(self.get_queryset(), name)(*args, **kwargs)
  File "E:\python3.6\lib\site-packages\django\db\models\query.py", line 836, in filter
    return self._filter_or_exclude(False, *args, **kwargs)
  File "E:\python3.6\lib\site-packages\django\db\models\query.py", line 854, in _filter_or_exclude
    clone.query.add_q(Q(*args, **kwargs))
  File "E:\python3.6\lib\site-packages\django\db\models\sql\query.py", line 1252, in add_q
    clause, _ = self._add_q(q_object, self.used_aliases)
  File "E:\python3.6\lib\site-packages\django\db\models\sql\query.py", line 1276, in _add_q
    split_subq=split_subq,
  File "E:\python3.6\lib\site-packages\django\db\models\sql\query.py", line 1186, in build_filter
    self.check_related_objects(join_info.final_field, value, join_info.opts)
  File "E:\python3.6\lib\site-packages\django\db\models\sql\query.py", line 1052, in check_related_objects
    for v in value:
  File "E:\python3.6\lib\site-packages\django\utils\functional.py", line 216, in inner
    return func(self._wrapped, *args)
TypeError: 'AnonymousUser' object is not iterable
[2019-09-19 09:55:25,019][Thread-47:13096][task_id:django.request][exception.py:118][ERROR][Internal Server Error: /blog/up_down/]
Traceback (most recent call last):
  File "J:\django_bbs\webbs\myapp\views\blog.py", line 114, in up_down
    models.ArticleUpDown.objects.create(user=user, article_id=article_id, is_up=is_up)
  File "E:\python3.6\lib\site-packages\django\db\models\manager.py", line 82, in manager_method
    return getattr(self.get_queryset(), name)(*args, **kwargs)
  File "E:\python3.6\lib\site-packages\django\db\models\query.py", line 415, in create
    obj = self.model(**kwargs)
  File "E:\python3.6\lib\site-packages\django\db\models\base.py", line 477, in __init__
    _setattr(self, field.name, rel_obj)
  File "E:\python3.6\lib\site-packages\django\db\models\fields\related_descriptors.py", line 197, in __set__
    self.field.remote_field.model._meta.object_name,
ValueError: Cannot assign "<SimpleLazyObject: <django.contrib.auth.models.AnonymousUser object at 0x003DFDB0>>": "ArticleUpDown.user" must be a "UserInfo" instance.

During handling of the above exception, another exception occurred:

Traceback (most recent call last):
  File "E:\python3.6\lib\site-packages\django\core\handlers\exception.py", line 35, in inner
    response = get_response(request)
  File "E:\python3.6\lib\site-packages\django\core\handlers\base.py", line 128, in _get_response
    response = self.process_exception_by_middleware(e, request)
  File "E:\python3.6\lib\site-packages\django\core\handlers\base.py", line 126, in _get_response
    response = wrapped_callback(request, *callback_args, **callback_kwargs)
  File "J:\django_bbs\webbs\myapp\views\blog.py", line 118, in up_down
    aa=models.ArticleUpDown.objects.filter(user=user, article_id=article_id).first().is_up
  File "E:\python3.6\lib\site-packages\django\db\models\manager.py", line 82, in manager_method
    return getattr(self.get_queryset(), name)(*args, **kwargs)
  File "E:\python3.6\lib\site-packages\django\db\models\query.py", line 836, in filter
    return self._filter_or_exclude(False, *args, **kwargs)
  File "E:\python3.6\lib\site-packages\django\db\models\query.py", line 854, in _filter_or_exclude
    clone.query.add_q(Q(*args, **kwargs))
  File "E:\python3.6\lib\site-packages\django\db\models\sql\query.py", line 1252, in add_q
    clause, _ = self._add_q(q_object, self.used_aliases)
  File "E:\python3.6\lib\site-packages\django\db\models\sql\query.py", line 1276, in _add_q
    split_subq=split_subq,
  File "E:\python3.6\lib\site-packages\django\db\models\sql\query.py", line 1186, in build_filter
    self.check_related_objects(join_info.final_field, value, join_info.opts)
  File "E:\python3.6\lib\site-packages\django\db\models\sql\query.py", line 1052, in check_related_objects
    for v in value:
  File "E:\python3.6\lib\site-packages\django\utils\functional.py", line 216, in inner
    return func(self._wrapped, *args)
TypeError: 'AnonymousUser' object is not iterable
[2019-09-19 09:55:25,745][Thread-48:13132][task_id:django.request][exception.py:118][ERROR][Internal Server Error: /blog/up_down/]
Traceback (most recent call last):
  File "J:\django_bbs\webbs\myapp\views\blog.py", line 114, in up_down
    models.ArticleUpDown.objects.create(user=user, article_id=article_id, is_up=is_up)
  File "E:\python3.6\lib\site-packages\django\db\models\manager.py", line 82, in manager_method
    return getattr(self.get_queryset(), name)(*args, **kwargs)
  File "E:\python3.6\lib\site-packages\django\db\models\query.py", line 415, in create
    obj = self.model(**kwargs)
  File "E:\python3.6\lib\site-packages\django\db\models\base.py", line 477, in __init__
    _setattr(self, field.name, rel_obj)
  File "E:\python3.6\lib\site-packages\django\db\models\fields\related_descriptors.py", line 197, in __set__
    self.field.remote_field.model._meta.object_name,
ValueError: Cannot assign "<SimpleLazyObject: <django.contrib.auth.models.AnonymousUser object at 0x046CBD30>>": "ArticleUpDown.user" must be a "UserInfo" instance.

During handling of the above exception, another exception occurred:

Traceback (most recent call last):
  File "E:\python3.6\lib\site-packages\django\core\handlers\exception.py", line 35, in inner
    response = get_response(request)
  File "E:\python3.6\lib\site-packages\django\core\handlers\base.py", line 128, in _get_response
    response = self.process_exception_by_middleware(e, request)
  File "E:\python3.6\lib\site-packages\django\core\handlers\base.py", line 126, in _get_response
    response = wrapped_callback(request, *callback_args, **callback_kwargs)
  File "J:\django_bbs\webbs\myapp\views\blog.py", line 118, in up_down
    aa=models.ArticleUpDown.objects.filter(user=user, article_id=article_id).first().is_up
  File "E:\python3.6\lib\site-packages\django\db\models\manager.py", line 82, in manager_method
    return getattr(self.get_queryset(), name)(*args, **kwargs)
  File "E:\python3.6\lib\site-packages\django\db\models\query.py", line 836, in filter
    return self._filter_or_exclude(False, *args, **kwargs)
  File "E:\python3.6\lib\site-packages\django\db\models\query.py", line 854, in _filter_or_exclude
    clone.query.add_q(Q(*args, **kwargs))
  File "E:\python3.6\lib\site-packages\django\db\models\sql\query.py", line 1252, in add_q
    clause, _ = self._add_q(q_object, self.used_aliases)
  File "E:\python3.6\lib\site-packages\django\db\models\sql\query.py", line 1276, in _add_q
    split_subq=split_subq,
  File "E:\python3.6\lib\site-packages\django\db\models\sql\query.py", line 1186, in build_filter
    self.check_related_objects(join_info.final_field, value, join_info.opts)
  File "E:\python3.6\lib\site-packages\django\db\models\sql\query.py", line 1052, in check_related_objects
    for v in value:
  File "E:\python3.6\lib\site-packages\django\utils\functional.py", line 216, in inner
    return func(self._wrapped, *args)
TypeError: 'AnonymousUser' object is not iterable
[2019-09-19 09:55:26,251][Thread-49:13232][task_id:django.request][exception.py:118][ERROR][Internal Server Error: /blog/up_down/]
Traceback (most recent call last):
  File "J:\django_bbs\webbs\myapp\views\blog.py", line 114, in up_down
    models.ArticleUpDown.objects.create(user=user, article_id=article_id, is_up=is_up)
  File "E:\python3.6\lib\site-packages\django\db\models\manager.py", line 82, in manager_method
    return getattr(self.get_queryset(), name)(*args, **kwargs)
  File "E:\python3.6\lib\site-packages\django\db\models\query.py", line 415, in create
    obj = self.model(**kwargs)
  File "E:\python3.6\lib\site-packages\django\db\models\base.py", line 477, in __init__
    _setattr(self, field.name, rel_obj)
  File "E:\python3.6\lib\site-packages\django\db\models\fields\related_descriptors.py", line 197, in __set__
    self.field.remote_field.model._meta.object_name,
ValueError: Cannot assign "<SimpleLazyObject: <django.contrib.auth.models.AnonymousUser object at 0x046ED350>>": "ArticleUpDown.user" must be a "UserInfo" instance.

During handling of the above exception, another exception occurred:

Traceback (most recent call last):
  File "E:\python3.6\lib\site-packages\django\core\handlers\exception.py", line 35, in inner
    response = get_response(request)
  File "E:\python3.6\lib\site-packages\django\core\handlers\base.py", line 128, in _get_response
    response = self.process_exception_by_middleware(e, request)
  File "E:\python3.6\lib\site-packages\django\core\handlers\base.py", line 126, in _get_response
    response = wrapped_callback(request, *callback_args, **callback_kwargs)
  File "J:\django_bbs\webbs\myapp\views\blog.py", line 118, in up_down
    aa=models.ArticleUpDown.objects.filter(user=user, article_id=article_id).first().is_up
  File "E:\python3.6\lib\site-packages\django\db\models\manager.py", line 82, in manager_method
    return getattr(self.get_queryset(), name)(*args, **kwargs)
  File "E:\python3.6\lib\site-packages\django\db\models\query.py", line 836, in filter
    return self._filter_or_exclude(False, *args, **kwargs)
  File "E:\python3.6\lib\site-packages\django\db\models\query.py", line 854, in _filter_or_exclude
    clone.query.add_q(Q(*args, **kwargs))
  File "E:\python3.6\lib\site-packages\django\db\models\sql\query.py", line 1252, in add_q
    clause, _ = self._add_q(q_object, self.used_aliases)
  File "E:\python3.6\lib\site-packages\django\db\models\sql\query.py", line 1276, in _add_q
    split_subq=split_subq,
  File "E:\python3.6\lib\site-packages\django\db\models\sql\query.py", line 1186, in build_filter
    self.check_related_objects(join_info.final_field, value, join_info.opts)
  File "E:\python3.6\lib\site-packages\django\db\models\sql\query.py", line 1052, in check_related_objects
    for v in value:
  File "E:\python3.6\lib\site-packages\django\utils\functional.py", line 216, in inner
    return func(self._wrapped, *args)
TypeError: 'AnonymousUser' object is not iterable
[2019-09-19 09:55:37,936][Thread-50:8796][task_id:django.request][exception.py:118][ERROR][Internal Server Error: /blog/up_down/]
Traceback (most recent call last):
  File "E:\python3.6\lib\site-packages\django\core\handlers\exception.py", line 35, in inner
    response = get_response(request)
  File "E:\python3.6\lib\site-packages\django\core\handlers\base.py", line 128, in _get_response
    response = self.process_exception_by_middleware(e, request)
  File "E:\python3.6\lib\site-packages\django\core\handlers\base.py", line 126, in _get_response
    response = wrapped_callback(request, *callback_args, **callback_kwargs)
  File "J:\django_bbs\webbs\myapp\views\blog.py", line 108, in up_down
    is_up = json.loads(request.POST.get('is_up'))
  File "E:\python3.6\lib\json\__init__.py", line 341, in loads
    raise TypeError(f'the JSON object must be str, bytes or bytearray, '
TypeError: the JSON object must be str, bytes or bytearray, not NoneType
[2019-09-19 09:55:55,932][Thread-52:12656][task_id:django.request][exception.py:118][ERROR][Internal Server Error: /blog/up_down/]
Traceback (most recent call last):
  File "J:\django_bbs\webbs\myapp\views\blog.py", line 114, in up_down
    models.ArticleUpDown.objects.create(user=user, article_id=article_id, is_up=is_up)
  File "E:\python3.6\lib\site-packages\django\db\models\manager.py", line 82, in manager_method
    return getattr(self.get_queryset(), name)(*args, **kwargs)
  File "E:\python3.6\lib\site-packages\django\db\models\query.py", line 415, in create
    obj = self.model(**kwargs)
  File "E:\python3.6\lib\site-packages\django\db\models\base.py", line 477, in __init__
    _setattr(self, field.name, rel_obj)
  File "E:\python3.6\lib\site-packages\django\db\models\fields\related_descriptors.py", line 197, in __set__
    self.field.remote_field.model._meta.object_name,
ValueError: Cannot assign "<SimpleLazyObject: <django.contrib.auth.models.AnonymousUser object at 0x046E9390>>": "ArticleUpDown.user" must be a "UserInfo" instance.

During handling of the above exception, another exception occurred:

Traceback (most recent call last):
  File "E:\python3.6\lib\site-packages\django\core\handlers\exception.py", line 35, in inner
    response = get_response(request)
  File "E:\python3.6\lib\site-packages\django\core\handlers\base.py", line 128, in _get_response
    response = self.process_exception_by_middleware(e, request)
  File "E:\python3.6\lib\site-packages\django\core\handlers\base.py", line 126, in _get_response
    response = wrapped_callback(request, *callback_args, **callback_kwargs)
  File "J:\django_bbs\webbs\myapp\views\blog.py", line 118, in up_down
    aa=models.ArticleUpDown.objects.filter(user=user, article_id=article_id).first().is_up
  File "E:\python3.6\lib\site-packages\django\db\models\manager.py", line 82, in manager_method
    return getattr(self.get_queryset(), name)(*args, **kwargs)
  File "E:\python3.6\lib\site-packages\django\db\models\query.py", line 836, in filter
    return self._filter_or_exclude(False, *args, **kwargs)
  File "E:\python3.6\lib\site-packages\django\db\models\query.py", line 854, in _filter_or_exclude
    clone.query.add_q(Q(*args, **kwargs))
  File "E:\python3.6\lib\site-packages\django\db\models\sql\query.py", line 1252, in add_q
    clause, _ = self._add_q(q_object, self.used_aliases)
  File "E:\python3.6\lib\site-packages\django\db\models\sql\query.py", line 1276, in _add_q
    split_subq=split_subq,
  File "E:\python3.6\lib\site-packages\django\db\models\sql\query.py", line 1186, in build_filter
    self.check_related_objects(join_info.final_field, value, join_info.opts)
  File "E:\python3.6\lib\site-packages\django\db\models\sql\query.py", line 1052, in check_related_objects
    for v in value:
  File "E:\python3.6\lib\site-packages\django\utils\functional.py", line 216, in inner
    return func(self._wrapped, *args)
TypeError: 'AnonymousUser' object is not iterable
[2019-09-19 09:55:56,723][Thread-54:6152][task_id:django.request][exception.py:118][ERROR][Internal Server Error: /blog/up_down/]
Traceback (most recent call last):
  File "J:\django_bbs\webbs\myapp\views\blog.py", line 114, in up_down
    models.ArticleUpDown.objects.create(user=user, article_id=article_id, is_up=is_up)
  File "E:\python3.6\lib\site-packages\django\db\models\manager.py", line 82, in manager_method
    return getattr(self.get_queryset(), name)(*args, **kwargs)
  File "E:\python3.6\lib\site-packages\django\db\models\query.py", line 415, in create
    obj = self.model(**kwargs)
  File "E:\python3.6\lib\site-packages\django\db\models\base.py", line 477, in __init__
    _setattr(self, field.name, rel_obj)
  File "E:\python3.6\lib\site-packages\django\db\models\fields\related_descriptors.py", line 197, in __set__
    self.field.remote_field.model._meta.object_name,
ValueError: Cannot assign "<SimpleLazyObject: <django.contrib.auth.models.AnonymousUser object at 0x046DEC50>>": "ArticleUpDown.user" must be a "UserInfo" instance.

During handling of the above exception, another exception occurred:

Traceback (most recent call last):
  File "E:\python3.6\lib\site-packages\django\core\handlers\exception.py", line 35, in inner
    response = get_response(request)
  File "E:\python3.6\lib\site-packages\django\core\handlers\base.py", line 128, in _get_response
    response = self.process_exception_by_middleware(e, request)
  File "E:\python3.6\lib\site-packages\django\core\handlers\base.py", line 126, in _get_response
    response = wrapped_callback(request, *callback_args, **callback_kwargs)
  File "J:\django_bbs\webbs\myapp\views\blog.py", line 118, in up_down
    aa=models.ArticleUpDown.objects.filter(user=user, article_id=article_id).first().is_up
  File "E:\python3.6\lib\site-packages\django\db\models\manager.py", line 82, in manager_method
    return getattr(self.get_queryset(), name)(*args, **kwargs)
  File "E:\python3.6\lib\site-packages\django\db\models\query.py", line 836, in filter
    return self._filter_or_exclude(False, *args, **kwargs)
  File "E:\python3.6\lib\site-packages\django\db\models\query.py", line 854, in _filter_or_exclude
    clone.query.add_q(Q(*args, **kwargs))
  File "E:\python3.6\lib\site-packages\django\db\models\sql\query.py", line 1252, in add_q
    clause, _ = self._add_q(q_object, self.used_aliases)
  File "E:\python3.6\lib\site-packages\django\db\models\sql\query.py", line 1276, in _add_q
    split_subq=split_subq,
  File "E:\python3.6\lib\site-packages\django\db\models\sql\query.py", line 1186, in build_filter
    self.check_related_objects(join_info.final_field, value, join_info.opts)
  File "E:\python3.6\lib\site-packages\django\db\models\sql\query.py", line 1052, in check_related_objects
    for v in value:
  File "E:\python3.6\lib\site-packages\django\utils\functional.py", line 216, in inner
    return func(self._wrapped, *args)
TypeError: 'AnonymousUser' object is not iterable
[2019-09-19 09:55:57,213][Thread-55:12480][task_id:django.request][exception.py:118][ERROR][Internal Server Error: /blog/up_down/]
Traceback (most recent call last):
  File "J:\django_bbs\webbs\myapp\views\blog.py", line 114, in up_down
    models.ArticleUpDown.objects.create(user=user, article_id=article_id, is_up=is_up)
  File "E:\python3.6\lib\site-packages\django\db\models\manager.py", line 82, in manager_method
    return getattr(self.get_queryset(), name)(*args, **kwargs)
  File "E:\python3.6\lib\site-packages\django\db\models\query.py", line 415, in create
    obj = self.model(**kwargs)
  File "E:\python3.6\lib\site-packages\django\db\models\base.py", line 477, in __init__
    _setattr(self, field.name, rel_obj)
  File "E:\python3.6\lib\site-packages\django\db\models\fields\related_descriptors.py", line 197, in __set__
    self.field.remote_field.model._meta.object_name,
ValueError: Cannot assign "<SimpleLazyObject: <django.contrib.auth.models.AnonymousUser object at 0x04791F70>>": "ArticleUpDown.user" must be a "UserInfo" instance.

During handling of the above exception, another exception occurred:

Traceback (most recent call last):
  File "E:\python3.6\lib\site-packages\django\core\handlers\exception.py", line 35, in inner
    response = get_response(request)
  File "E:\python3.6\lib\site-packages\django\core\handlers\base.py", line 128, in _get_response
    response = self.process_exception_by_middleware(e, request)
  File "E:\python3.6\lib\site-packages\django\core\handlers\base.py", line 126, in _get_response
    response = wrapped_callback(request, *callback_args, **callback_kwargs)
  File "J:\django_bbs\webbs\myapp\views\blog.py", line 118, in up_down
    aa=models.ArticleUpDown.objects.filter(user=user, article_id=article_id).first().is_up
  File "E:\python3.6\lib\site-packages\django\db\models\manager.py", line 82, in manager_method
    return getattr(self.get_queryset(), name)(*args, **kwargs)
  File "E:\python3.6\lib\site-packages\django\db\models\query.py", line 836, in filter
    return self._filter_or_exclude(False, *args, **kwargs)
  File "E:\python3.6\lib\site-packages\django\db\models\query.py", line 854, in _filter_or_exclude
    clone.query.add_q(Q(*args, **kwargs))
  File "E:\python3.6\lib\site-packages\django\db\models\sql\query.py", line 1252, in add_q
    clause, _ = self._add_q(q_object, self.used_aliases)
  File "E:\python3.6\lib\site-packages\django\db\models\sql\query.py", line 1276, in _add_q
    split_subq=split_subq,
  File "E:\python3.6\lib\site-packages\django\db\models\sql\query.py", line 1186, in build_filter
    self.check_related_objects(join_info.final_field, value, join_info.opts)
  File "E:\python3.6\lib\site-packages\django\db\models\sql\query.py", line 1052, in check_related_objects
    for v in value:
  File "E:\python3.6\lib\site-packages\django\utils\functional.py", line 216, in inner
    return func(self._wrapped, *args)
TypeError: 'AnonymousUser' object is not iterable
[2019-09-19 09:55:57,407][Thread-56:12760][task_id:django.request][exception.py:118][ERROR][Internal Server Error: /blog/up_down/]
Traceback (most recent call last):
  File "J:\django_bbs\webbs\myapp\views\blog.py", line 114, in up_down
    models.ArticleUpDown.objects.create(user=user, article_id=article_id, is_up=is_up)
  File "E:\python3.6\lib\site-packages\django\db\models\manager.py", line 82, in manager_method
    return getattr(self.get_queryset(), name)(*args, **kwargs)
  File "E:\python3.6\lib\site-packages\django\db\models\query.py", line 415, in create
    obj = self.model(**kwargs)
  File "E:\python3.6\lib\site-packages\django\db\models\base.py", line 477, in __init__
    _setattr(self, field.name, rel_obj)
  File "E:\python3.6\lib\site-packages\django\db\models\fields\related_descriptors.py", line 197, in __set__
    self.field.remote_field.model._meta.object_name,
ValueError: Cannot assign "<SimpleLazyObject: <django.contrib.auth.models.AnonymousUser object at 0x046CB4D0>>": "ArticleUpDown.user" must be a "UserInfo" instance.

During handling of the above exception, another exception occurred:

Traceback (most recent call last):
  File "E:\python3.6\lib\site-packages\django\core\handlers\exception.py", line 35, in inner
    response = get_response(request)
  File "E:\python3.6\lib\site-packages\django\core\handlers\base.py", line 128, in _get_response
    response = self.process_exception_by_middleware(e, request)
  File "E:\python3.6\lib\site-packages\django\core\handlers\base.py", line 126, in _get_response
    response = wrapped_callback(request, *callback_args, **callback_kwargs)
  File "J:\django_bbs\webbs\myapp\views\blog.py", line 118, in up_down
    aa=models.ArticleUpDown.objects.filter(user=user, article_id=article_id).first().is_up
  File "E:\python3.6\lib\site-packages\django\db\models\manager.py", line 82, in manager_method
    return getattr(self.get_queryset(), name)(*args, **kwargs)
  File "E:\python3.6\lib\site-packages\django\db\models\query.py", line 836, in filter
    return self._filter_or_exclude(False, *args, **kwargs)
  File "E:\python3.6\lib\site-packages\django\db\models\query.py", line 854, in _filter_or_exclude
    clone.query.add_q(Q(*args, **kwargs))
  File "E:\python3.6\lib\site-packages\django\db\models\sql\query.py", line 1252, in add_q
    clause, _ = self._add_q(q_object, self.used_aliases)
  File "E:\python3.6\lib\site-packages\django\db\models\sql\query.py", line 1276, in _add_q
    split_subq=split_subq,
  File "E:\python3.6\lib\site-packages\django\db\models\sql\query.py", line 1186, in build_filter
    self.check_related_objects(join_info.final_field, value, join_info.opts)
  File "E:\python3.6\lib\site-packages\django\db\models\sql\query.py", line 1052, in check_related_objects
    for v in value:
  File "E:\python3.6\lib\site-packages\django\utils\functional.py", line 216, in inner
    return func(self._wrapped, *args)
TypeError: 'AnonymousUser' object is not iterable
[2019-09-19 09:56:11,801][Thread-57:9608][task_id:django.request][exception.py:118][ERROR][Internal Server Error: /blog/up_down/]
Traceback (most recent call last):
  File "E:\python3.6\lib\site-packages\django\core\handlers\exception.py", line 35, in inner
    response = get_response(request)
  File "E:\python3.6\lib\site-packages\django\core\handlers\base.py", line 128, in _get_response
    response = self.process_exception_by_middleware(e, request)
  File "E:\python3.6\lib\site-packages\django\core\handlers\base.py", line 126, in _get_response
    response = wrapped_callback(request, *callback_args, **callback_kwargs)
  File "J:\django_bbs\webbs\myapp\views\blog.py", line 108, in up_down
    is_up = json.loads(request.POST.get('is_up'))
  File "E:\python3.6\lib\json\__init__.py", line 341, in loads
    raise TypeError(f'the JSON object must be str, bytes or bytearray, '
TypeError: the JSON object must be str, bytes or bytearray, not NoneType
[2019-09-19 13:39:41,017][Thread-6:13644][task_id:django.request][exception.py:118][ERROR][Internal Server Error: /blog/comment_tree/2/]
Traceback (most recent call last):
  File "E:\python3.6\lib\site-packages\django\core\handlers\exception.py", line 35, in inner
    response = get_response(request)
  File "E:\python3.6\lib\site-packages\django\core\handlers\base.py", line 128, in _get_response
    response = self.process_exception_by_middleware(e, request)
  File "E:\python3.6\lib\site-packages\django\core\handlers\base.py", line 126, in _get_response
    response = wrapped_callback(request, *callback_args, **callback_kwargs)
TypeError: comment_tree() missing 1 required positional argument: 'article_id'
[2019-09-19 13:39:57,403][Thread-12:11464][task_id:django.request][exception.py:118][ERROR][Internal Server Error: /blog/comment_tree/4/]
Traceback (most recent call last):
  File "E:\python3.6\lib\site-packages\django\core\handlers\exception.py", line 35, in inner
    response = get_response(request)
  File "E:\python3.6\lib\site-packages\django\core\handlers\base.py", line 128, in _get_response
    response = self.process_exception_by_middleware(e, request)
  File "E:\python3.6\lib\site-packages\django\core\handlers\base.py", line 126, in _get_response
    response = wrapped_callback(request, *callback_args, **callback_kwargs)
TypeError: comment_tree() missing 1 required positional argument: 'article_id'
[2019-09-19 13:40:06,537][Thread-16:4304][task_id:django.request][exception.py:118][ERROR][Internal Server Error: /blog/comment_tree/3/]
Traceback (most recent call last):
  File "E:\python3.6\lib\site-packages\django\core\handlers\exception.py", line 35, in inner
    response = get_response(request)
  File "E:\python3.6\lib\site-packages\django\core\handlers\base.py", line 128, in _get_response
    response = self.process_exception_by_middleware(e, request)
  File "E:\python3.6\lib\site-packages\django\core\handlers\base.py", line 126, in _get_response
    response = wrapped_callback(request, *callback_args, **callback_kwargs)
TypeError: comment_tree() missing 1 required positional argument: 'article_id'
[2019-09-19 13:40:13,021][Thread-18:1904][task_id:django.request][exception.py:118][ERROR][Internal Server Error: /blog/comment_tree/8/]
Traceback (most recent call last):
  File "E:\python3.6\lib\site-packages\django\core\handlers\exception.py", line 35, in inner
    response = get_response(request)
  File "E:\python3.6\lib\site-packages\django\core\handlers\base.py", line 128, in _get_response
    response = self.process_exception_by_middleware(e, request)
  File "E:\python3.6\lib\site-packages\django\core\handlers\base.py", line 126, in _get_response
    response = wrapped_callback(request, *callback_args, **callback_kwargs)
TypeError: comment_tree() missing 1 required positional argument: 'article_id'
[2019-09-19 13:48:39,504][Thread-9:13556][task_id:django.request][exception.py:118][ERROR][Internal Server Error: /blog/comment_tree/8/]
Traceback (most recent call last):
  File "E:\python3.6\lib\site-packages\django\core\handlers\exception.py", line 35, in inner
    response = get_response(request)
  File "E:\python3.6\lib\site-packages\django\core\handlers\base.py", line 128, in _get_response
    response = self.process_exception_by_middleware(e, request)
  File "E:\python3.6\lib\site-packages\django\core\handlers\base.py", line 126, in _get_response
    response = wrapped_callback(request, *callback_args, **callback_kwargs)
TypeError: comment_tree() missing 1 required positional argument: 'article_id'
[2019-09-19 13:48:50,325][Thread-11:11332][task_id:django.request][exception.py:118][ERROR][Internal Server Error: /blog/comment_tree/8/]
Traceback (most recent call last):
  File "E:\python3.6\lib\site-packages\django\core\handlers\exception.py", line 35, in inner
    response = get_response(request)
  File "E:\python3.6\lib\site-packages\django\core\handlers\base.py", line 128, in _get_response
    response = self.process_exception_by_middleware(e, request)
  File "E:\python3.6\lib\site-packages\django\core\handlers\base.py", line 126, in _get_response
    response = wrapped_callback(request, *callback_args, **callback_kwargs)
TypeError: comment_tree() missing 1 required positional argument: 'article_id'
[2019-09-19 13:52:22,380][Thread-3:7232][task_id:django.request][exception.py:118][ERROR][Internal Server Error: /blog/comment_tree/8/]
Traceback (most recent call last):
  File "E:\python3.6\lib\site-packages\django\core\handlers\exception.py", line 35, in inner
    response = get_response(request)
  File "E:\python3.6\lib\site-packages\django\core\handlers\base.py", line 128, in _get_response
    response = self.process_exception_by_middleware(e, request)
  File "E:\python3.6\lib\site-packages\django\core\handlers\base.py", line 126, in _get_response
    response = wrapped_callback(request, *callback_args, **callback_kwargs)
TypeError: comment_tree() missing 1 required positional argument: 'article_id'
[2019-09-19 13:52:52,798][Thread-6:5372][task_id:django.request][exception.py:118][ERROR][Internal Server Error: /blog/comment_tree/8/]
Traceback (most recent call last):
  File "E:\python3.6\lib\site-packages\django\core\handlers\exception.py", line 35, in inner
    response = get_response(request)
  File "E:\python3.6\lib\site-packages\django\core\handlers\base.py", line 128, in _get_response
    response = self.process_exception_by_middleware(e, request)
  File "E:\python3.6\lib\site-packages\django\core\handlers\base.py", line 126, in _get_response
    response = wrapped_callback(request, *callback_args, **callback_kwargs)
TypeError: comment_tree() missing 1 required positional argument: 'article_id'
[2019-09-19 15:08:43,890][Thread-1:15348][task_id:django.request][exception.py:118][ERROR][Internal Server Error: /add_upload/]
Traceback (most recent call last):
  File "E:\python3.6\lib\site-packages\django\core\handlers\exception.py", line 35, in inner
    response = get_response(request)
  File "E:\python3.6\lib\site-packages\django\core\handlers\base.py", line 128, in _get_response
    response = self.process_exception_by_middleware(e, request)
  File "E:\python3.6\lib\site-packages\django\core\handlers\base.py", line 126, in _get_response
    response = wrapped_callback(request, *callback_args, **callback_kwargs)
  File "J:\django_bbs\webbs\myapp\views\blog.py", line 188, in add_upload
    for line in obj:
FileNotFoundError: [Errno 2] No such file or directory: 'J:\\django_bbs\\webbs\\media\\add_img\\timg.jpg'
[2019-09-19 15:58:00,842][Thread-10:10436][task_id:django.request][exception.py:118][ERROR][Internal Server Error: /blog/add/]
Traceback (most recent call last):
  File "E:\python3.6\lib\site-packages\django\core\handlers\exception.py", line 35, in inner
    response = get_response(request)
  File "E:\python3.6\lib\site-packages\django\core\handlers\base.py", line 128, in _get_response
    response = self.process_exception_by_middleware(e, request)
  File "E:\python3.6\lib\site-packages\django\core\handlers\base.py", line 126, in _get_response
    response = wrapped_callback(request, *callback_args, **callback_kwargs)
  File "J:\django_bbs\webbs\myapp\views\blog.py", line 179, in add_article
    from bs4 import BeautifulSoup
ModuleNotFoundError: No module named 'bs4'
[2019-09-19 15:58:11,354][Thread-11:14984][task_id:django.request][exception.py:118][ERROR][Internal Server Error: /blog/add/]
Traceback (most recent call last):
  File "E:\python3.6\lib\site-packages\django\core\handlers\exception.py", line 35, in inner
    response = get_response(request)
  File "E:\python3.6\lib\site-packages\django\core\handlers\base.py", line 128, in _get_response
    response = self.process_exception_by_middleware(e, request)
  File "E:\python3.6\lib\site-packages\django\core\handlers\base.py", line 126, in _get_response
    response = wrapped_callback(request, *callback_args, **callback_kwargs)
  File "J:\django_bbs\webbs\myapp\views\blog.py", line 179, in add_article
    from bs4 import BeautifulSoup
ModuleNotFoundError: No module named 'bs4'
[2019-09-19 15:58:53,283][Thread-14:10644][task_id:django.request][exception.py:118][ERROR][Internal Server Error: /blog/add/]
Traceback (most recent call last):
  File "E:\python3.6\lib\site-packages\django\core\handlers\exception.py", line 35, in inner
    response = get_response(request)
  File "E:\python3.6\lib\site-packages\django\core\handlers\base.py", line 128, in _get_response
    response = self.process_exception_by_middleware(e, request)
  File "E:\python3.6\lib\site-packages\django\core\handlers\base.py", line 126, in _get_response
    response = wrapped_callback(request, *callback_args, **callback_kwargs)
  File "J:\django_bbs\webbs\myapp\views\blog.py", line 179, in add_article
    from bs4 import BeautifulSoup
ModuleNotFoundError: No module named 'bs4'
